Workbook

Sheet README
A1: Final Search, Selection, and PRISMA Supplement — Corpus n = 22
A3: Item | B3: Final status
A4: Final search date | B4: 2 September 2026
A5: Eligibility window | B5: January 2015 through 2 September 2026; no calendar-year 2025 cutoff
A6: Final coded corpus | B6: 22
A7: Database-derived inclusions | B7: 17
A8: Supplementary inclusions | B8: 5
A9: Original route | B9: 180 occurrences; 8 duplicates; 172 unique; 15 final inclusions after reassessment
A10: Sensitivity route | B10: 103 occurrences; 16 duplicates; 87 unique; 28 already assessed/included; 59 new; 0 new inclusions
A11: Final update route | B11: 76 occurrences; 17 duplicates; 59 unique; 20 already assessed; 39 new; 2 inclusions
A12: Scope | B12: Journal reviews in which RL and operational control/energy management of occupied residential or commercial buildings are central and separable. Grid-service, electricity-market, and EV-centered reviews are outside the quantitative scope.
A13: Deduplication | B13: Exact DOI followed by normalized-title matching (case, punctuation, accents, and whitespace removed).
A14: Route-neutral eligibility | B14: Discovery route was recorded for provenance but did not determine eligibility; every record was assessed against the same final criteria.
A15: Historical-stage limitation | B15: The contemporaneous split of the original 172 records between title/abstract exclusion and full-text exclusion was not retained. This workbook reports that original route as a combined eligibility-assessment stage rather than inventing counts.
A16: Reviewer involvement | B16: Screening was performed by a single reviewer. Inclusion eligibility for all 22 reviews was independently assessed by a co-author. Coding reliability was estimated on a stratified random subsample of six reviews (27%) coded independently by a co-author against the same decision rules: across 786 survey–dimension pairs, exact agreement 72.6%, agreement within one scale level 92.2%, linear-weighted Cohen's kappa 0.71 (see inter_rater_reliability_six_reviews.xlsx). Single-reviewer screening remains stated as a limitation in the manuscript.
A17: Prepared for | B17: Revision of EAI-D-26-00659

Sheet PRISMA Accounting
A1: Reconciled Route-Based PRISMA Accounting
A3: Route | B3: Raw occurrences | C3: Duplicate occurrences | D3: Previously assessed / already included | E3: Distinct records screened | F3: Included from route | G3: Excluded from route | H3: Known title/abstract exclusions | I3: Known full texts assessed | J3: Known full-text exclusions
A4: Original cumulative search | B4: 180 | C4: 8 | D4: 0 | E4: =B4-C4-D4 -> 172 | F4: 15 | G4: =E4-F4 -> 157 | H4: Not retained | I4: Not retained | J4: See close-exclusion register
A5: Expanded sensitivity | B5: 103 | C5: 16 | D5: 28 | E5: =B5-C5-D5 -> 59 | F5: 0 | G5: =E5-F5 -> 59 | H5: Not reported separately | I5: 1 close scope reassessment | J5: 1 (Sajid et al.)
A6: Final main-query update | B6: 76 | C6: 17 | D6: 20 | E6: =B6-C6-D6 -> 39 | F6: 2 | G6: =E6-F6 -> 37 | H6: 33 | I6: 6 | J6: 4
A7: Database-route totals | B7: =SUM(B4:B6) -> 359 | C7: =SUM(C4:C6) -> 41 | D7: =SUM(D4:D6) -> 48 | E7: =SUM(E4:E6) -> 270 | F7: =SUM(F4:F6) -> 17 | G7: =SUM(G4:G6) -> 253
A9: Final-corpus reconciliation | B9: Count
A10: Database-derived included reviews | B10: =F7 -> 17
A11: Supplementary included reviews | B11: 5
A12: Final coded corpus | B12: =B10+B11 -> 22
A13: Check | B13: =IF(B12=22,"PASS","CHECK") -> PASS
A15: Interpretive note | B15: Value
A16: Combined raw occurrences | B16: 359 across three distinct search routes; not a single undifferentiated database search
A17: Distinct database records actually screened | B17: 270 after route-specific deduplication and removal of records already assessed through earlier routes
A18: Historical stage reporting | B18: Original 172 are reported as one eligibility-assessment stage because the contemporaneous title/abstract versus full-text split was not preserved

Sheet Search Log
A1: Search Dates, Databases, and Verified Counts
A3: Route | B3: Database/export | C3: Search date | D3: Year filter | E3: Raw occurrences | F3: Unique after route deduplication | G3: Prior records removed | H3: Notes
A4: Original cumulative | B4: Web of Science | C4: 46197 | D4: 2015–2026-06-24 | E4: 56 | H4: Initial search 5 Feb 2025; cumulative export updated 24 Jun 2026
A5: Original cumulative | B5: ScienceDirect | C5: 46197 | D5: 2015–2026-06-24 | E5: 70 | H5: Initial search 5 Feb 2025; cumulative export updated 24 Jun 2026
A6: Original cumulative | B6: IEEE Xplore | C6: 46197 | D6: 2015–2026-06-24 | E6: 54 | H6: Initial search 5 Feb 2025; cumulative export updated 24 Jun 2026
A7: Original total | B7: All three | C7: 46197 | E7: 180 | F7: 172 | G7: 0 | H7: 8 duplicates removed
A8: Expanded sensitivity | B8: Web of Science | C8: 46265 | D8: 2015–2026 | E8: 60 | H8: Broader system-level domain terms
A9: Expanded sensitivity | B9: ScienceDirect A | C9: 46265 | D9: 2015–2026 | E9: 5 | H9: Boolean-limit split A
A10: Expanded sensitivity | B10: ScienceDirect B | C10: 46265 | D10: 2015–2026 | E10: 15 | H10: Boolean-limit split B
A11: Expanded sensitivity | B11: IEEE Xplore | C11: 46265 | D11: 2015–2026 | E11: 23 | H11: All publication types retained initially
A12: Sensitivity total | B12: All three | C12: 46265 | E12: 103 | F12: 87 | G12: 28 | H12: 16 duplicates; 25 original matches + Latoń + Michailidis + Sierla already in corpus; 59 new
A13: Final main-query update | B13: Web of Science | C13: 46267 | D13: 2025–2026 | E13: 26 | H13: Original main concept query rerun
A14: Final main-query update | B14: ScienceDirect A | C14: 46267 | D14: 2025–2026 | E14: 19 | H14: Boolean-limit split A
A15: Final main-query update | B15: ScienceDirect B | C15: 46267 | D15: 2025–2026 | E15: 16 | H15: Boolean-limit split B
A16: Final main-query update | B16: IEEE Xplore | C16: 46267 | D16: 2025–2026 | E16: 15 | H16: Original main concept query rerun
A17: Final update total | B17: All three | C17: 46267 | E17: 76 | F17: 59 | G17: 20 | H17: 17 duplicates; 12 original + 8 sensitivity records already assessed; 39 new

Sheet Search Strings
A1: Database-Specific Search Strings and Filters
A3: Route | B3: Database | C3: Fields | D3: Exact query / implementation | E3: Filters | F3: Provenance note
A4: Original + final update | B4: Web of Science | C4: Topic (TS) + Title (TI) | D4: TS=(("reinforcement learning" OR "deep reinforcement learning" OR "multi-agent reinforcement learning") AND ("building automation" OR "building energy management" OR "home energy management" OR "HVAC" OR "smart building" OR "building energy" OR "thermal comfort")) AND TI=(review OR survey OR overview OR "systematic literature review") | E4: English; 2015–24 Jun 2026 cumulatively; rerun for 2025–2 Sep 2026 | F4: Historical export does not embed query history; syntax reproduces the manuscript-recorded concept blocks
A5: Original + final update | B5: IEEE Xplore | C5: All Metadata + Document Title | D5: (("reinforcement learning" OR "deep reinforcement learning" OR "multi-agent reinforcement learning")) AND (("building automation" OR "building energy management" OR "home energy management" OR "HVAC" OR "smart building" OR "building energy" OR "thermal comfort")) AND (Document Title: review OR survey OR overview OR "systematic literature review") | E5: English; 2015–24 Jun 2026 cumulatively; rerun for 2025–2 Sep 2026 | F5: Platform-compatible transcription of the recorded concept blocks
A6: Original + final update A | B6: ScienceDirect | C6: Title/abstract/keywords + Title | D6: ("reinforcement learning" OR "deep reinforcement learning" OR "multi-agent reinforcement learning") AND ("building automation" OR "building energy management" OR "home energy management" OR "HVAC"); Title: review OR survey OR overview OR "systematic literature review" | E6: English; relevant date range | F6: Split to respect the maximum-eight-connectors limit per field
A7: Original + final update B | B7: ScienceDirect | C7: Title/abstract/keywords + Title | D7: ("reinforcement learning" OR "deep reinforcement learning" OR "multi-agent reinforcement learning") AND ("smart building" OR "building energy" OR "thermal comfort"); Title: review OR survey OR overview OR "systematic literature review" | E7: English; relevant date range | F7: Split to respect the maximum-eight-connectors limit per field
A8: Expanded sensitivity | B8: Web of Science | C8: Topic (TS) + Title (TI) | D8: TS=((("reinforcement learning" OR "deep reinforcement learning" OR "multi-agent reinforcement learning")) AND ("building cluster*" OR "multi-building*" OR "multiple building*" OR "district heating" OR "district energy" OR "district cooling" OR "energy communit*" OR "building microgrid*" OR "grid-interactive building*" OR "grid-responsive building*" OR "demand response")) AND TI=(review OR survey OR overview OR "systematic literature review") | E8: English; 2015–2026 | F8: Exact recorded sensitivity query
A9: Expanded sensitivity | B9: IEEE Xplore | C9: All Metadata + Document Title | D9: ("All Metadata":"reinforcement learning" OR "All Metadata":"deep reinforcement learning" OR "All Metadata":"multi-agent reinforcement learning") AND ("All Metadata":"building cluster*" OR "All Metadata":"multi-building*" OR "All Metadata":"multiple building*" OR "All Metadata":"district heating" OR "All Metadata":"district energy" OR "All Metadata":"district cooling" OR "All Metadata":"energy communit*" OR "All Metadata":"building microgrid*" OR "All Metadata":"grid-interactive building*" OR "All Metadata":"grid-responsive building*" OR "All Metadata":"demand response") AND ("Document Title":review OR "Document Title":survey OR "Document Title":overview OR "Document Title":"systematic literature review") | E9: English; 2015–2026 | F9: Exact recorded sensitivity query
A10: Expanded sensitivity A | B10: ScienceDirect | C10: Title/abstract/keywords + Title | D10: ("reinforcement learning" OR "deep reinforcement learning" OR "multi-agent reinforcement learning") AND ("building cluster" OR "multi-building" OR "multiple building" OR "district heating" OR "district energy" OR "district cooling"); Title: review OR survey OR overview OR "systematic literature review" | E10: English; 2015–2026 | F10: Exact recorded query A
A11: Expanded sensitivity B | B11: ScienceDirect | C11: Title/abstract/keywords + Title | D11: ("reinforcement learning" OR "deep reinforcement learning" OR "multi-agent reinforcement learning") AND ("energy community" OR "building microgrid" OR "grid-interactive building" OR "grid-responsive building" OR "demand response"); Title: review OR survey OR overview OR "systematic literature review" | E11: English; 2015–2026 | F11: Exact recorded query B

Sheet Eligibility Codebook
A1: Final Eligibility Criteria and Decision Rules
A3: Dimension | B3: Include when | C3: Exclude when | D3: Evidence checked | E3: Primary exclusion label | F3: Final scope clarification
A4: Publication type | B4: Full peer-reviewed journal review, survey, systematic review, or comprehensive review | C4: Primary study, conference paper, chapter, thesis, report, preprint, corrigendum, letter, or short non-review format | D4: Article type, venue, length, review structure | E4: Wrong publication type | F4: Contextual records may be discussed but are not coded
A5: Language/access | B5: English full text accessible | C5: Non-English or full text unavailable | D5: Full text and bibliographic record | E5: Language/full text unavailable | F5: No eligible record was excluded solely by publication year
A6: RL centrality | B6: RL/DRL/MARL organizes the objectives, study selection, taxonomy, comparisons, or synthesis | C6: RL is one method in a broader AI, ML, optimization, MPC, or control review | D6: Objectives, eligibility, tables, taxonomy, proportion devoted to RL | E6: RL not central | F6: A prominent RL paragraph alone is insufficient
A7: Building-control centrality | B7: Control or energy management of occupied residential or commercial buildings is a central and separable review domain | C7: Grid, markets, EVs, industrial systems, agriculture, or general control dominate | D7: Research questions, taxonomy, included-study distribution | E7: Building control not central | F7: Buildings must be explicit controllable units
A8: Included subsystems | B8: HVAC, thermal comfort, HEMS/BEMS, lighting, storage, renewables, BIPV, occupant-centric control | C8: Occupant modelling without a control decision; non-building assets | D8: State/action/objective and application scope | E8: Outside building-control scope | F8: Multi-building/district work qualifies only when building-control findings are separable
A9: Grid interaction boundary | B9: Building-side control remains central; grid signal is an input or constraint | C9: Grid services, market participation, or power-system operation is the principal synthesis | D9: System boundary and controlled resources | E9: Outside declared grid scope | F9: The final quantitative corpus intentionally excludes grid-interaction reviews centered on grid services
A10: Independence | B10: Distinct review and evidence base | C10: Duplicate, corrigendum, or substantially overlapping synthesis | D10: Authors, abstract, tables, primary-study set | E10: Duplicate/overlapping review | F10: Two applications. The Mazhar Next Energy record is excluded in favour of the independent IET review. Han et al. (2019), Sustainable Cities and Society 51:101748, is excluded as a companion report of the same review programme as the included Han et al. (2021): the 2021 review states which primary studies it excludes and refers the reader to the 2019 review for them, so the two partition a single evidence base. The criterion is triggered by a declared partition of the evidence base, not by shared authorship alone; Li et al. (2025) and Lei et al. (2026) share three authors but select on orthogonal axes and neither refers excluded literature to the other, so both are retained.
A11: Date | B11: Published and available by 2 September 2026 | C11: Available only after the final search date | D11: Online publication/index date | E11: Outside date window | F11: Eligibility begins January 2015; no December 2025 cutoff

Sheet Included 22
A1: Final Included Review Corpus (n = 22)
A3: Corpus ID | B3: Title | C3: Authors | D3: Year | E3: Venue | F3: DOI | G3: Inclusion route | H3: Corpus status | I3: Database-derived? | J3: Inclusion rationale
A4: INC-01 | B4: A review of reinforcement learning for autonomous building energy management | C4: Mason, Karl; Grijalva, Santiago | D4: 2019 | E4: Computers & Electrical Engineering | F4: 10.1016/j.compeleceng.2019.07.019 | G4: Original database search | H4: Pre-existing corpus | I4: Yes | J4: Eligible journal review with RL and operational building control or energy management as central and separable subjects.
A5: INC-02 | B5: The reinforcement learning method for occupant behavior in building control: A review | C5: Han, Mengjie; Zhao, Jing; Zhang, Xingxing; Shen, Jingchun; Li, Yu | D5: 2021 | E5: Energy and Built Environment | F5: 10.1016/j.enbenv.2020.08.005 | G5: Original database search | H5: Pre-existing corpus | I5: Yes | J5: Eligible journal review with RL and operational building control or energy management as central and separable subjects.
A6: INC-03 | B6: Reinforcement learning for building controls: The opportunities and challenges | C6: Wang, Zhe; Hong, Tianzhen | D6: 2020 | E6: Applied Energy | F6: 10.1016/j.apenergy.2020.115036 | G6: Original database search | H6: Pre-existing corpus | I6: Yes | J6: Eligible journal review with RL and operational building control or energy management as central and separable subjects.
A7: INC-04 | B7: A Review of Deep Reinforcement Learning for Smart Building Energy Management | C7: Yu, L; Qin, SQ; Zhang, M; Shen, C; Jiang, T; Guan, XH | D7: 2021 | E7: IEEE INTERNET OF THINGS JOURNAL | F7: 10.1109/jiot.2021.3078462 | G7: Original database search | H7: Pre-existing corpus | I7: Yes | J7: Eligible journal review with RL and operational building control or energy management as central and separable subjects.
A8: INC-05 | B8: A review of reinforcement learning applications to control of heating, ventilation and air conditioning systems | C8: Sierla, Seppo; Ihasalo, Heikki; Vyatkin, Valeriy | D8: 2022 | E8: Energies | F8: 10.3390/en15103526 | G8: Supplementary/citation searching; later retrieved by sensitivity search | H8: Pre-existing corpus; provenance corrected | I8: No | J8: Eligible journal review with RL and HVAC control as central and separable subjects.
A9: INC-06 | B9: Applications of reinforcement learning for building energy efficiency control: A review | C9: Fu, Qiming; Han, Zhicong; Chen, Jianping; Lu, You; Wu, Hongjie; Wang, Yunzhe | D9: 2022 | E9: Journal of Building Engineering | F9: 10.1016/j.jobe.2022.104165 | G9: Original database search | H9: Pre-existing corpus | I9: Yes | J9: Eligible journal review with RL and operational building control or energy management as central and separable subjects.
A10: INC-07 | B10: Building Energy Management With Reinforcement Learning and Model Predictive Control: A Survey | C10: H. Zhang; S. Seal; D. Wu; F. Bouffard; B. Boulet | D10: 2022 | E10: IEEE Access | F10: 10.1109/access.2022.3156581 | G10: Original database search | H10: Pre-existing corpus | I10: Yes | J10: Eligible journal review with RL and operational building control or energy management as central and separable subjects.
A11: INC-08 | B11: Reinforcement Learning: Theory and Applications in HEMS | C11: Al-Ani, O; Das, S | D11: 2022 | E11: ENERGIES | F11: 10.3390/en15176392 | G11: Original database search | H11: Pre-existing corpus | I11: Yes | J11: Eligible journal review with RL and operational building control or energy management as central and separable subjects.
A12: INC-09 | B12: Systematic Review on Deep Reinforcement Learning-Based Energy Management for Different Building Types | C12: Shaqour, Ayas; Hagishima, Aya | D12: 2022 | E12: Energies | F12: 10.3390/en15228663 | G12: Supplementary Google Scholar search | H12: Pre-existing corpus | I12: No | J12: Eligible journal review with RL and building energy management as central and separable subjects.
A13: INC-10 | B13: A Review of Reinforcement Learning for Controlling Building Energy Systems From a Computer Science Perspective | C13: Weinberg, David; Wang, Qian; Timoudas, Thomas Ohlson; Fischione, Carlo | D13: 2023 | E13: Sustainable Cities and Society | F13: 10.1016/j.scs.2022.104351 | G13: Original database search | H13: Pre-existing corpus | I13: Yes | J13: Eligible journal review with RL and operational building control or energy management as central and separable subjects.
A14: INC-11 | B14: Dynamic indoor thermal environment using Reinforcement Learning-based controls: Opportunities and challenges | C14: Chatterjee, Arnab; Khovalyg, Dolaana | D14: 2023 | E14: Building and Environment | F14: 10.1016/j.buildenv.2023.110766 | G14: Original database search | H14: Pre-existing corpus | I14: Yes | J14: Eligible journal review with RL and operational building control or energy management as central and separable subjects.
A15: INC-12 | B15: An overview of reinforcement learning-based approaches for smart home energy management systems with energy storages | C15: Pinthurat, W; Surinkaew, T; Hredzak, B | D15: 2024 | E15: RENEWABLE & SUSTAINABLE ENERGY REVIEWS | F15: 10.1016/j.rser.2024.114648 | G15: Original database search | H15: Pre-existing corpus | I15: Yes | J15: Eligible journal review with RL and operational building control or energy management as central and separable subjects.
... A25: INC-22 | B25: Hybrid Reinforcement Learning for occupant-centric building control: A review and deployment framework for co-optimizing energy, comfort, and indoor air quality | C25: Mohsenpour, Majid; Xing, Yangang | D25: 2026 | E25: Applied Energy | F25: 10.1016/j.apenergy.2026.127392 | G25: Supplementary publisher/citation searching | H25: Added during revision | I25: No | J25: RL structures the occupant-centric building-control review and deployment synthesis; energy, comfort, and indoor-air-quality control are the central building-side objectives.

Sheet Provenance 22
A1: Discovery Provenance of the 22 Included Reviews
A2: Export presence columns record whether the review appears in the preserved raw RIS exports for each route, verified by DOI and normalised-title matching against all eleven export files. They document retrievability, not the route through which the review was actually first obtained.
A4: Corpus ID | B4: Review | C4: Year | D4: DOI | E4: Documented discovery route | F4: Corpus status | G4: In original export | H4: In sensitivity export | I4: In final-update export | J4: Evidence basis for the stated route
A5: INC-01 | B5: Mason et al. (2019) | C5: 2019 | D5: 10.1016/j.compeleceng.2019.07.019 | E5: Original database search | F5: Pre-existing corpus | G5: Yes | H5: No | I5: No | J5: Present in the preserved original cumulative export (24 Jun 2026).
A6: INC-02 | B6: Han et al. (2021) | C6: 2021 | D6: 10.1016/j.enbenv.2020.08.005 | E6: Original database search | F6: Pre-existing corpus | G6: Yes | H6: No | I6: No | J6: Present in the preserved original cumulative export (24 Jun 2026), record ORI-059.
A7: INC-03 | B7: Wang et al. (2020) | C7: 2020 | D7: 10.1016/j.apenergy.2020.115036 | E7: Original database search | F7: Pre-existing corpus | G7: Yes | H7: No | I7: No | J7: Present in the preserved original cumulative export (24 Jun 2026).
A8: INC-04 | B8: Yu et al. (2021) | C8: 2021 | D8: 10.1109/jiot.2021.3078462 | E8: Original database search | F8: Pre-existing corpus | G8: Yes | H8: Yes | I8: No | J8: Present in the preserved original cumulative export (24 Jun 2026). Also returned by the sensitivity route.
A9: INC-05 | B9: Sierla et al. (2022) | C9: 2022 | D9: 10.3390/en15103526 | E9: Supplementary/citation searching; later retrieved by sensitivity search | F9: Pre-existing corpus; provenance corrected | G9: No | H9: Yes | I9: No | J9: Belonged to the pre-existing coded corpus but is absent from the preserved original export; the original discovery log was not retained and no specific backward-citation source is claimed. Independently retrieved by the 31 Aug 2026 sensitivity search (DOI 10.3390/en15103526, record SENS-036), which corroborates retrievability.
A10: INC-06 | B10: Fu et al. (2022) | C10: 2022 | D10: 10.1016/j.jobe.2022.104165 | E10: Original database search | F10: Pre-existing corpus | G10: Yes | H10: No | I10: No | J10: Present in the preserved original cumulative export (24 Jun 2026).
A11: INC-07 | B11: H. Zhang et al. (2022) | C11: 2022 | D11: 10.1109/access.2022.3156581 | E11: Original database search | F11: Pre-existing corpus | G11: Yes | H11: No | I11: No | J11: Present in the preserved original cumulative export (24 Jun 2026).
A12: INC-08 | B12: Al-Ani et al. (2022) | C12: 2022 | D12: 10.3390/en15176392 | E12: Original database search | F12: Pre-existing corpus | G12: Yes | H12: No | I12: No | J12: Present in the preserved original cumulative export (24 Jun 2026).
A13: INC-09 | B13: Shaqour et al. (2022) | C13: 2022 | D13: 10.3390/en15228663 | E13: Supplementary Google Scholar search | F13: Pre-existing corpus | G13: No | H13: No | I13: No | J13: Located during the original study using the same search concepts. Absent from all preserved exports and never re-retrieved by a later route; earliest documented route reported. Direct Google Scholar find, so no parent citation trail applies.
A14: INC-10 | B14: Weinberg et al. (2023) | C14: 2023 | D14: 10.1016/j.scs.2022.104351 | E14: Original database search | F14: Pre-existing corpus | G14: Yes | H14: Yes | I14: No | J14: Present in the preserved original cumulative export (24 Jun 2026). Also returned by the sensitivity route.
A15: INC-11 | B15: Chatterjee et al. (2023) | C15: 2023 | D15: 10.1016/j.buildenv.2023.110766 | E15: Original database search | F15: Pre-existing corpus | G15: Yes | H15: No | I15: No | J15: Present in the preserved original cumulative export (24 Jun 2026).
... A26: INC-22 | B26: Mohsenpour et al. (2026) | C26: 2026 | D26: 10.1016/j.apenergy.2026.127392 | E26: Supplementary publisher/citation searching | F26: Added during revision | G26: No | H26: No | I26: No | J26: Identified during revision through publisher and institutional searching. Absent from all preserved exports, consistent with publication after the 2 Sep 2026 export queries were framed; earliest documented route reported.
A28: Note on supplementary records
A29: For supplementary records whose original discovery log was not retained, the earliest documented route is reported. No specific backward-citation source is claimed where it could not be reconstructed.
A31: Summary
A32: Traceable to a preserved database export | B32: 20
A33: of which present in the original cumulative export | B33: 15
A34: of which present only in the final main-query update | B34: 2
A35: of which present only in the expanded sensitivity export | B35: 3
A36: Absent from every preserved export | B36: 2
A37: Database-derived per the inclusion route column | B37: 17
A38: Supplementary-route inclusions | B38: 5
A39: Total | B39: 22

Sheet Original 172
A1: Original Cumulative Search — 172 Unique Records
A3: Original ID | B3: Sources | C3: Occurrence count | D3: Title | E3: Authors | F3: Year | G3: Type | H3: Venue | I3: DOI | J3: Final decision | K3: Primary reason | L3: Assessment stage | M3: Decision note | N3: Source files | O3: Abstract
A4: ORI-045 | B4: Web of Science | C4: 1 | D4: A bibliometric analysis and review on reinforcement learning for transportation applications | E4: Li, C; Bai, L; Yao, LA; Waller, ST; Liu, W | F4: 2023 | G4: JOUR | H4: TRANSPORTMETRICA B-TRANSPORT DYNAMICS | I4: 10.1080/21680566.2023.2179461 | J4: Exclude | K4: Building control is not the central application domain | L4: Historical eligibility assessment | M4: The historical title/abstract versus full-text split was not retained; reason reconstructed from the final scope and available record metadata. | N4: wos_final.ris
A5: ORI-131 | B5: IEEE Xplore | C5: 1 | D5: A Comprehensive Review of Energy Management Strategies in Hybrid Electric Vehicles: Comparative Analysis and Challenges | E5: V. Chandra Tella; M. Alzayed; H. Chaoui | F5: 2024 | G5: JOUR | H5: IEEE Access | I5: 10.1109/access.2024.3509737 | J5: Exclude | K5: Reinforcement learning is not the central review subject | L5: Historical eligibility assessment | M5: The historical title/abstract versus full-text split was not retained; reason reconstructed from the final scope and available record metadata. | N5: ieee_final.ris | O5: As air pollution, greenhouse gases, and global warming worsen, finding clean energy sources is critical. Renewable energy is a promising solution, especially in the transportation sector, which consumes significant energy. Hybrid electric vehicles (HEVs), combining an internal combustion engine and an electric battery, are key to reducing fossil fuel use and mitigating environmental harm. Effectively managing power distribution between these sources to enhance efficiency and minimize fuel consumption is crucial, known as an Energy Management Strategy (EMS). This article provides an overview of various EMS approaches for HEVs, analyzing their advantages and disadvantages. Rule-based strategies offer simplicity, optimization-based strategies provide superior performance, and advanced techniques like machine learning promise significant improvements. Current trends include integrating sophisticated sensors, data analytics, and artificial intelligence for real-time decision-making. Future directions aim at robust EMS frameworks integrating smart grid technologies and vehicle-to-everything (V2X) communication. The article reviews EMS methodologies, comparing their strengths and weaknesses, and discusses the main challenges and future trends in energy management for hybrid electric vehicles.
A6: ORI-105 | B6: ScienceDirect | C6: 1 | D6: A comprehensive review of machine learning and IoT solutions for demand side energy management, conservation, and resilient operation | E6: Elsisi, Mahmoud; Amer, Mohammed; Dababat, Alya’; Su, Chun-Lien | F6: 2023 | G6: JOUR | H6: Energy | I6: 10.1016/j.energy.2023.128256 | J6: Exclude | K6: Reinforcement learning is not the central review subject | L6: Historical eligibility assessment | M6: The historical title/abstract versus full-text split was not retained; reason reconstructed from the final scope and available record metadata. | N6: ScienceDirect_citations_1783952383784(1).ris | O6: The energy consumption of major equipment in residential and industrial facilities can be minimized through a variety of cost-effective energy-saving measures. Most saving strategies are economically viable where several algorithms can be employed to reduce energy consumption to reduce costs to a considerable extent. Machine learning (ML) is one of these techniques. A review of recent research efforts concerning the application of ML strategies to energy conservation and management problems is presented in this study. In addition, ML approaches and strategies for energy-saving problems, management, technologies, and control methods have been discussed. A comprehensive review of all available publications is also used to make observations about past considerations. As a result, it has been concluded that ML is capable of solving a wide range of decision and management problems within a short period of time with minimal energy consumption. In addition, ML perspectives have been viewed from the perspective of emerging communication technologies, instruments, and cyber-physical systems (CPSs), along with the advancement of ultra-durable and energy-efficient Internet-of-Things (IoT) based communication sensors technology. Moreover, a comprehensive review of recent developments in ML algorithms is also included, including safe reinforcement learning (RL), Deep RL, path integral control for RL, and others not previously. Lastly, critical ML considerations such as emergency and remedial measures, integrity protection, fusion with existing robust controls, and combining preventive and emergent measures have been discussed. The implementation of recently applied ML, RL, and IoT strategies for energy management, conservation, and resilient operation is clarified in this paper. The proposed review highlights the advantages and drawbacks of the recent energy conservation strategies. Finally, the perspective solutions have been clarified to cope with the world direction for zero energy buildings.
A7: ORI-115 | B7: ScienceDirect | C7: 1 | D7: A comprehensive review of predictive control strategies in heating, ventilation, and air-conditioning (HVAC): Model-free VS model | E7: Xin, Xin; Zhang, Zhihao; Zhou, Yong; Liu, Yanfeng; Wang, Dengjia; Nan, Shuo | F7: 2024 | G7: JOUR | H7: Journal of Building Engineering | I7: 10.1016/j.jobe.2024.110013 | J7: Exclude | K7: Reinforcement learning is not the central review subject | L7: Historical eligibility assessment | M7: The historical title/abstract versus full-text split was not retained; reason reconstructed from the final scope and available record metadata. | N7: ScienceDirect_citations_1783952383784(1).ris | O7: Predictive control offers significant advantages in nonlinear control, high thermal inertia, and dynamic control. This article uses a Systematic Reviews and Meta-Analyses methodology to review 245 studies on predictive control in HVAC systems over the past 12 years, focusing on Model Predictive Control (MPC) and Model-Free Predictive Control (MFPC). In cooling systems, MPC is widely applied to energy efficiency management, continuous operation and maintenance, and overall system optimization in multi-zone residences. Its advantage is its ability to respond to system dynamics and precisely control key components such as cooling towers, condensers, evaporators, and pumps. Research focuses on simplifying models, reducing computational complexity, and enhancing real-time performance. In contrast, MFPC saves energy in equipment components and overall operation through intelligent valves, agent control programs, and other methods. Research focuses on developing new reinforcement learning algorithms to improve control efficiency and reliability. MPC research in heating systems focuses on hydraulic and thermal balance in central heating systems and expands to managing renewable energy hybrid systems. The research aims to dynamically adjust to meet user thermal comfort requirements while reducing energy consumption and improving efficiency. Key technologies include modeling techniques, distributed MPC, cross-regional integrated control, and efficient renewable energy integration strategies. MFPC precisely controls heating system water supply temperature, heat pump energy efficiency, and heating terminals through model-free algorithms like deep reinforcement learning and multivariable extremum seeking control. In integrated HVAC systems, MPC research focuses on managing multi-energy systems through hierarchical decomposition and multi-layer strategies, seamless renewable energy integration and optimization, and developing multi-objective optimization and decision support tools. MFPC research includes automatic grading strategies for integrated controllers, online optimization balancing methods, multi-agent methods, and developing intelligent model-free adaptive control strategies. However, MFPC integration in practical applications still needs strengthening. This review guides researchers in selecting the best predictive control mode for various HVAC system applications.
A8: ORI-134 | B8: IEEE Xplore | C8: 1 | D8: A Comprehensive Review of Reinforcement Learning Algorithms for Control Systems: Applications, Challenges, and Future Directions | E8: A. H. Abdul Hafez; U. Demircioglu; H. Bakir; R. Alzubi | F8: 2026 | G8: JOUR | H8: IEEE Access | I8: 10.1109/access.2026.3674539 | J8: Exclude | K8: Building control is not the central application domain | L8: Historical eligibility assessment | M8: The historical title/abstract versus full-text split was not retained; reason reconstructed from the final scope and available record metadata. | N8: ieee_final.ris | O8: Reinforcement Learning (RL) has emerged as a powerful paradigm for optimizing control systems by enabling autonomous decision-making in dynamic environments. This review provides a comprehensive analysis of RL algorithms applied to control systems, including robotics, industrial automation, and dynamic system control. A systematic review of more than 300 research papers was conducted to assess the advantages, limitations, and real-world applicability of various RL approaches. The study categorizes RL algorithms based on their applicability to discrete and continuous control problems and evaluates their effectiveness in comparison with traditional control techniques. Additionally, this review examines the integration of RL with conventional control strategies, highlighting the impact of such integration on adaptive learning, system efficiency, and decision optimization. Key challenges associated with RL in control applications, such as computational complexity, data efficiency, and generalization issues, are also discussed. By synthesizing existing literature and identifying research gaps, this review serves as a foundational resource for researchers and practitioners aiming to advance RL-driven control systems.
A9: ORI-140 | B9: IEEE Xplore | C9: 1 | D9: A Comprehensive Review of Topologies and Energy Management Methods for Hybrid Energy Storage Systems in Electric Vehicle Applications | E9: P. Ranjbaran; J. Ebrahimi; A. Bakhshai; P. K. Jain | F9: 2026 | G9: JOUR | H9: IEEE Transactions on Power Electronics | I9: 10.1109/tpel.2025.3625535 | J9: Exclude | K9: Reinforcement learning is not the central review subject | L9: Historical eligibility assessment | M9: The historical title/abstract versus full-text split was not retained; reason reconstructed from the final scope and available record metadata. | N9: ieee_final.ris | O9: Hybrid energy storage systems (HESSs), combining batteries and supercapacitors (SCs), have emerged as a promising solution to address the conflicting demands of high energy density, power density, and cycle life in electric vehicles (EVs). This article presents a comprehensive and up-to-date review of power converter topologies and energy management strategies (EMSs) for HESS integration in EVs. First, this article systematically classifies converter architectures into dual-stage, single-stage, and quasi-stage topologies to analyze their operational principles, control flexibility, efficiency, and suitability for modern EV applications. Detailed comparisons of semiactive, fully active, multi-input, and reconfigurable dual-stage converters, as well as advanced single-stage multisource inverter (MSI) configurations along with quasi-single-stage and quasi-dual-stage topologies, are provided. Next, the EMSs applicable to HESSs in EVs are reviewed and categorized into rule-based, optimization-based, machine learning (ML)-based, and hybrid methodologies. Recent advances in ML, particularly reinforcement learning algorithms, are critically examined for their potential in enabling adaptive, model-free energy management under complex and uncertain driving conditions. Comprehensive tables and comparative analyzes highlight the strengths, limitations, and validation methods of leading techniques. Finally, this article identifies key trends, technical challenges, and research gaps, and discusses future research directions to guide the codesign of converter topologies and intelligent EMSs for next-generation EVs.
A10: ORI-109 | B10: ScienceDirect | C10: 1 | D10: A critical review of field implementation of data-driven operation and maintenance technologies to reduce building energy use and GHG emissions | E10: Gunay, Burak; Markus, Andre; Parsaei, Arya; Darwazeh, Darwish; Bursill, Jayson; Pellerin, Luc | F10: 2025 | G10: JOUR | H10: Energy and Buildings | I10: 10.1016/j.enbuild.2025.116087 | J10: Exclude | K10: RL is one of six data-driven operation and maintenance application domains | L10: Full-text reassessment | M10: RL-specific evidence is not the organizing subject | N10: ScienceDirect_citations_1783952383784(1).ris | O10: Field implementation studies spanning six data-driven building operation and maintenance (DBOM) application domains (model-based predictive control (MPC), occupant-centric control (OCC), automated demand response (ADR), reinforcement learning control (RLC), fault detection and diagnostics (FDD), and virtual metering (VM)) were reviewed. The review aimed to make inter- and intra-application domain comparisons in terms of implementation processes and outcomes. The studies were classified by different levels of integration effort and sensing infrastructure complexity according to the quantity and kind of their inputs and outputs. An analysis is conducted on how energy-related success metrics (e.g., energy use, cost, demand) correlate with the integration effort and the complexity of the infrastructure. In general, MPC and ADR studies were found to require a higher level of integration effort than OCC studies; yet, OCC studies tend to require upgrades in the sensing infrastructure, unlike MPC and ADR studies. 95 % of those reporting post-implementation energy metrics achieved more than 10 % improvement in their energy-related objectives. The analysis results also highlight that a large fraction of the FDD and VM studies did not follow a measurement and verification procedure to quantify energy-related performance improvements upon field implementation. 90 % of the papers did not include feedback from building operators or occupants after the implementation.
A11: ORI-083 | B11: ScienceDirect | C11: 1 | D11: A critical review of safe reinforcement learning strategies in power and energy systems | E11: Bui, Van-Hai; Mohammadi, Sina; Das, Srijita; Hussain, Akhtar; Hollweg, Guilherme Vieira; Su, Wencong | F11: 2025 | G11: JOUR | H11: Engineering Applications of Artificial Intelligence | I11: 10.1016/j.engappai.2025.110091 | J11: Exclude | K11: Did not satisfy all centrality, publication-type, or scope criteria in the final eligibility assessment | L11: Historical eligibility assessment | M11: The historical title/abstract versus full-text split was not retained; reason reconstructed from the final scope and available record metadata. | N11: ScienceDirect_citations_1783952383784(1).ris | O11: The high penetration of distributed energy resources (DERs) in modern smart power systems introduces unforeseen uncertainties for the electricity sector, leading to increased complexity and difficulty in the operation and control of power systems. As a cutting-edge machine learning technology, deep reinforcement learning (DRL) has been widely implemented in recent years to handle the uncertainty in power systems. However, in critical infrastructures such as power systems, safety issues always receive top priority, while DRL may not always meet the safety requirements of power system operators. The concept of safe reinforcement learning (safe RL) is emerging as a potential solution to overcome the shortcomings of conventional DRL in the operation and control of power systems. This study provides a rigorous review of the latest research efforts focused on safe RL to derive power system control policies while accounting for the unique safety requirements of power grids. Furthermore, this study highlights various safe RL algorithms applied in diverse applications within the power and energy system sector, from single grid-connected power converters, residential smart homes, and buildings to large power distribution networks. For all methods outlined, a discussion on their bottlenecks, research challenges, and potential opportunities in the operation and control of power system applications is also presented. This review aims to support research in the area of safe RL algorithms, embracing smart power system operation with safety constraints amid high uncertainty from DERs.
A12: ORI-037 | B12: Web of Science | C12: 1 | D12: A Meta-Survey on Intelligent Energy-Efficient Buildings | E12: Islam, MB; Guerrieri, A; Gravina, R; Fortino, G | F12: 2024 | G12: JOUR | H12: BIG DATA AND COGNITIVE COMPUTING | I12: 10.3390/bdcc8080083 | J12: Exclude | K12: Reinforcement learning is not the central review subject | L12: Historical eligibility assessment | M12: The historical title/abstract versus full-text split was not retained; reason reconstructed from the final scope and available record metadata. | N12: wos_final.ris
A13: ORI-170 | B13: IEEE Xplore | C13: 1 | D13: A multi-faceted approach to electricity theft detection: Using community engagement, audit analytics, and machine learning algorithms | E13: C. A. Sibiya; K. A. Ogudo; E. Aladesanmi | F13: 2026 | G13: JOUR | H13: SAIEE Africa Research Journal | I13: 10.23919/saiee.2026.11484067 | J13: Exclude | K13: Not an eligible review/survey publication | L13: Historical eligibility assessment | M13: The historical title/abstract versus full-text split was not retained; reason reconstructed from the final scope and available record metadata. | N13: ieee_final.ris | O13: Electricity theft represents a significant source of non-technical losses (NTLs) in power distribution networks, leading to substantial financial deficits, grid instability, and safety concerns. This study introduces a machine learning-based methodology to detect and predict electricity theft by examining residential consumption patterns in Pietermaritzburg Municipality, South Africa. Utilising meter data from approximately 42,000 customers, of whom 21,935 made at least one electricity purchase over a five-year period (2019-2024), the research evaluates five machine learning techniques: decision trees, logistic regression, K-nearest neighbours, XGBoost, and random forests. The approach integrates survey data, audit outcomes, and audit evaluations for a holistic analysis. Results indicate that Random Forest outperforms other models, achieving the highest scores across accuracy (0.8), precision (0.75), recall (0.9), and F1-score (0.82) for detecting tampering. Survey findings reveal that 85.0% of respondents link theft to financial hardship, underscoring socio-economic influences. This study provides utilities with practical insights to reduce NTLs, enhance grid reliability, and foster sustainable energy management.
A14: ORI-077 | B14: ScienceDirect | C14: 1 | D14: A review of advanced ground source heat pump control: Artificial intelligence for autonomous and adaptive control | E14: Noye, Sarah; Mulero Martinez, Rubén; Carnieletto, Laura; De Carli, Michele; Castelruiz Aguirre, Amaia | F14: 2022 | G14: JOUR | H14: Renewable and Sustainable Energy Reviews | I14: 10.1016/j.rser.2021.111685 | J14: Exclude | K14: Reinforcement learning is not the central review subject | L14: Historical eligibility assessment | M14: The historical title/abstract versus full-text split was not retained; reason reconstructed from the final scope and available record metadata. | N14: ScienceDirect_citations_1783952383784(1).ris | O14: Geothermal energy has the potential to contribute significantly to the CO2 reduction targets as a renewable source for building heating and cooling but is yet under exploited, mostly due to its high initial investment cost. A lot of research is being carried out to optimise Ground Source Heat Pump (GSHP) systems’ design, but a good control strategy is also fundamental to achieve long-term performance and reduced payback time. GSHP control optimisation is a non-linear dynamic optimisation problem that is influenced by multiple parameters. It can thus not be fully optimised with traditional methods. Artificial Intelligence, and in particular Machine Learning, is suited for this type of optimisation as it can learn implicit relations between parameters and can address non-linearity. This paper reviews the challenges of GSHP control and the strategies for control optimisation found in the literature, from basic rule-based system to artificial neural network-based strategies. Two principal uses of Artificial Intelligence for ground source heat pump control are identified: building a predictive model of the system that reflects its real performances and optimising the control decision in real time. However, the examples found in the literature are limited and the need to further explore the benefits of Machine Learning is identified. The latest developments in the field are reviewed to explore their potential to further improve GSHP control. The challenges of the full implementation of such algorithms are also discussed.
A15: ORI-042 | B15: Web of Science | C15: 1 | D15: A review of building climate and plant controls, and a survey of industry perspectives | E15: Royapoor, M; Antony, A; Roskilly, T | F15: 2018 | G15: JOUR | H15: ENERGY AND BUILDINGS | I15: 10.1016/j.enbuild.2017.10.022 | J15: Exclude | K15: Reinforcement learning is not the central review subject | L15: Historical eligibility assessment | M15: The historical title/abstract versus full-text split was not retained; reason reconstructed from the final scope and available record metadata. | N15: wos_final.ris
A16: ORI-027 | B16: Web of Science; IEEE Xplore | C16: 2 | D16: A Review of Deep Reinforcement Learning for Smart Building Energy Management | E16: Yu, L; Qin, SQ; Zhang, M; Shen, C; Jiang, T; Guan, XH | F16: 2021 | G16: JOUR | H16: IEEE INTERNET OF THINGS JOURNAL | I16: 10.1109/jiot.2021.3078462 | J16: Include | K16: Eligible in the pre-existing coded corpus | L16: Full-text eligibility | M16: Final corpus | N16: wos_final.ris; ieee_final.ris
A17: ORI-034 | B17: Web of Science | C17: 1 | D17: A Review of Denial of Service Attack and Mitigation in the Smart Grid Using Reinforcement Learning | E17: Ortega-Fernandez, I; Liberati, F | F17: 2023 | G17: JOUR | H17: ENERGIES | I17: 10.3390/en16020635 | J17: Exclude | K17: Building control is not the central application domain | L17: Historical eligibility assessment | M17: The historical title/abstract versus full-text split was not retained; reason reconstructed from the final scope and available record metadata. | N17: wos_final.ris
A18: ORI-075 | B18: ScienceDirect | C18: 1 | D18: A review of reinforcement learning for autonomous building energy management | E18: Mason, Karl; Grijalva, Santiago | F18: 2019 | G18: JOUR | H18: Computers & Electrical Engineering | I18: 10.1016/j.compeleceng.2019.07.019 | J18: Include | K18: Eligible in the pre-existing coded corpus | L18: Full-text eligibility | M18: Final corpus | N18: ScienceDirect_citations_1783952383784(1).ris | O18: The area of building energy management has received a significant amount of interest in recent years. This area is concerned with combining advancements in sensor technologies, communications and advanced control algorithms to optimize energy utilization. Reinforcement learning is one of the most prominent machine learning algorithms used for control problems and has had many successful applications in the area of building energy management. This research gives a comprehensive review of the literature relating to the application of reinforcement learning to developing autonomous building energy management systems. Energy savings of greater than 20% are reported in the literature for more complex building energy management problems when implementing reinforcement learning. The main direction for future research and challenges in reinforcement learning are also outlined.
A19: ORI-022 | B19: Web of Science; ScienceDirect | C19: 2 | D19: A Review of Reinforcement Learning for Controlling Building Energy Systems From a Computer Science Perspective | E19: Weinberg, David; Wang, Qian; Timoudas, Thomas Ohlson; Fischione, Carlo | F19: 2023 | G19: JOUR | H19: Sustainable Cities and Society | I19: 10.1016/j.scs.2022.104351 | J19: Include | K19: Eligible in the pre-existing coded corpus | L19: Full-text eligibility | M19: Final corpus | N19: wos_final.ris; ScienceDirect_citations_1783952383784(1).ris | O19: Energy efficient control of energy systems in buildings is a widely recognized challenge due to the use of low temperature heating, renewable electricity sources, and the incorporation of thermal storage. Reinforcement Learning (RL) has been shown to be effective at minimizing the energy usage in buildings with maintained thermal comfort despite the high system complexity. However, RL has certain disadvantages that make it challenging to apply in engineering practices. In this review, we take a computer science approach to identifying three main categories of challenges of using RL for control of Building Energy Systems (BES). The three categories are the following: RL in single buildings, RL in building clusters, and multi-agent aspects. For each topic, we analyse the main challenges, and the state-of-the-art approaches to alleviate them. We also identify several future research directions on subjects such as sample efficiency, transfer learning, and the theoretical properties of RL in building energy systems. In conclusion, our review shows that the work on RL for BES control is still in its initial stages. Although significant progress has been made, more research is needed to realize the goal of RL-based control of BES at scale.
A20: ORI-093 | B20: ScienceDirect | C20: 1 | D20: A review of reinforcement learning methodologies for controlling occupant comfort in buildings | E20: Han, Mengjie; May, Ross; Zhang, Xingxing; Wang, Xinru; Pan, Song; Yan, Da; Jin, Yuan; Xu, Liguo | F20: 2019 | G20: JOUR | H20: Sustainable Cities and Society | I20: 10.1016/j.scs.2019.101748 | J20: Exclude | K20: Duplicate/overlapping review | L20: Historical eligibility assessment | M20: Identified during revision; this record had been mislabelled as the coded Han corpus member, and the coded member is Han et al. (2021), ORI-059. Excluded under the Independence criterion as a companion report of the same review programme. Han et al. (2021), the coded corpus member, states in its own Section 2.2 that "an agent that tried to learn the optimal control strategy only to satisfy occupant comfort and did not include dynamic interactions with the environment was excluded from this analysis. See a relevant review work [24] that examined the RL control for occupant comfort for more articles that we exclude here", where its reference [24] is this record. The two reviews therefore partition one evidence base between them. Because the unit of analysis in this tertiary review is the review, counting both companion reports would double-weight one team's editorial choices in every research-question denominator. The later report, whose scope is RL within building control with occupant behaviour inside the MDP, is retained. | N20: ScienceDirect_citations_1783952383784(1).ris | O20: Classical building control systems are becoming vulnerable with increasing complexities in contemporary built environments and energy systems. Due to this, the reinforcement learning (RL) method is becoming more distinctive and applicable in control networks for buildings. This paper, therefore, conducts a comprehensive review of RL techniques applied in control systems for occupant comfort in indoor built environments. The empirical applications of RL-based control systems are presented, depending on comfort objectives (thermal comfort, indoor air quality, and lighting) along with other objectives which invariably includes energy consumption. The class of RL algorithms and implementation details regarding how the value functions have been represented and how the policies are improved are also illustrated. This paper shows there are limited works for which RL has been explored for controlling occupant comfort, especially in indoor air quality and lighting. Relatively few of the reviewed works incorporate occupancy patterns and/or occupant feedback into the control loop. Moreover, this paper identifies a gap with regard to the performance of implementing cooperative multi-agent RL (MARL). Based on our findings, current challenges and further opportunities are discussed. We expect to clarify the feasible theory and functions of RL for building control systems, which would promote their wider-spread application in built environments.
A21: ORI-144 | B21: IEEE Xplore | C21: 1 | D21: A Review of Safe Reinforcement Learning Methods for Modern Power Systems | E21: T. Su; T. Wu; J. Zhao; A. Scaglione; L. Xie | F21: 2025 | G21: JOUR | H21: Proceedings of the IEEE | I21: 10.1109/jproc.2025.3584656 | J21: Exclude | K21: Building control is not the central application domain | L21: Historical eligibility assessment | M21: The historical title/abstract versus full-text split was not retained; reason reconstructed from the final scope and available record metadata. | N21: ieee_final.ris | O21: Given the availability of more comprehensive measurement data in modern power systems, reinforcement learning (RL) has gained significant interest in operation and control. Conventional RL relies on trial-and-error interactions with the environment and reward feedback, which often leads to exploring unsafe operating regions and executing unsafe actions, especially when deployed in real-world power systems. To address these challenges, safe RL has been proposed to optimize operational objectives while ensuring safety constraints are met, keeping actions and states within safe regions throughout both training and deployment. Rather than relying solely on manually designed penalty terms for unsafe actions, as is common in conventional RL, safe RL methods reviewed here primarily leverage advanced and proactive mechanisms. These include techniques such as Lagrangian relaxation, safety layers, and theoretical guarantees like Lyapunov functions to rigorously enforce safety boundaries. This article provides a comprehensive review of safe RL methods and their applications across various power system operations and control domains, including security control, real-time operation, operational planning, and emerging areas. It summarizes existing safe RL techniques, evaluates their performance, analyzes suitable deployment scenarios, and examines algorithm benchmarks and application environments. This article also highlights real-world implementation cases and identifies critical challenges such as scalability in large-scale systems and robustness under uncertainty, providing potential solutions and outlining future directions to advance the reliable integration and deployment of safe RL in modern power systems.
A22: ORI-138 | B22: IEEE Xplore | C22: 1 | D22: A Review on Optimal Energy Management of Multimicrogrid System Considering Uncertainties | E22: G. Ma; J. Li; X. -P. Zhang | F22: 2022 | G22: JOUR | H22: IEEE Access | I22: 10.1109/access.2022.3192638 | J22: Exclude | K22: Reinforcement learning is not the central review subject | L22: Historical eligibility assessment | M22: The historical title/abstract versus full-text split was not retained; reason reconstructed from the final scope and available record metadata. | N22: ieee_final.ris | O22: Microgrid (MG) is one of the most effective solution to integrate distributed renewable energy into power system. However, modern MG has several technical challenges such as migration to multi vector energy system, increasing renewable energy penetration, and the uncertainties that arise from the large-scale incorporation of renewable energy. Recent development of multi-microgrid (MMG) could potentially mitigate these challenges. MMG has obvious advantages in improving the system stability, reliability, economy, and energy efficiency of power grid operation through autonomous management and coordinated control among networked MGs. In the meantime, uncertainties from many elements and operators in the MMG system also pose huge challenges in modeling. This paper will present and review typical architecture of MMG, including physical layer, information layer and application layer. Moreover, this paper will critically review and analyze challenges in uncertainty modelling and solution in MMGs. Finally, the paper will also discuss future research areas and development trends of MMG.
A23: ORI-038 | B23: Web of Science | C23: 1 | D23: A state-of-the-art review and bibliometric analysis on the sizing optimization of off-grid hybrid renewable energy systems | E23: He, Y; Guo, S; Dong, PX; Zhang, Y; Huang, J; Zhou, JX | F23: 2023 | G23: JOUR | H23: RENEWABLE & SUSTAINABLE ENERGY REVIEWS | I23: 10.1016/j.rser.2023.113476 | J23: Exclude | K23: Reinforcement learning is not the central review subject | L23: Historical eligibility assessment | M23: The historical title/abstract versus full-text split was not retained; reason reconstructed from the final scope and available record metadata. | N23: wos_final.ris
A24: ORI-032 | B24: Web of Science | C24: 1 | D24: A survey for deep reinforcement learning in markovian cyber-physical systems: Common problems and solutions | E24: Rupprecht, T; Wang, YZ | F24: 2022 | G24: JOUR | H24: NEURAL NETWORKS | I24: 10.1016/j.neunet.2022.05.013 | J24: Exclude | K24: Building control is not the central application domain | L24: Historical eligibility assessment | M24: The historical title/abstract versus full-text split was not retained; reason reconstructed from the final scope and available record metadata. | N24: wos_final.ris
